import { ILocalDatabase } from '../utils/local-database';
import { PerformanceMonitorService } from './performance-monitor.service';

interface IErrorRecord {
  /** id 的描述 */
  id: string;
  /** error 的描述 */
  error: Error;
  /** context 的描述 */
  context: any;
  /** timestamp 的描述 */
  timestamp: Date;
  /** retryCount 的描述 */
  retryCount: number;
  /** resolved 的描述 */
  resolved: boolean;
}

export class ErrorRecoveryService {
  private db: ILocalDatabase;
  private monitor: PerformanceMonitorService;
  private maxRetries = 3;
  private retryDelay = 1000;

  constructor() {
    this.db = new LocalDatabase('error-recovery');
    this.monitor = new PerformanceMonitorService();
  }

  async handleError(error: Error, context: any, operation: () => Promise<any>): Promise<any> {
    const errorRecord: IErrorRecord = {
      id: `${Date.now()}-${Math.random()}`,
      error,
      context,
      timestamp: new Date(),
      retryCount: 0,
      resolved: false,
    };

    await this.saveErrorRecord(errorRecord);

    return this.retryOperation(errorRecord, operation);
  }

  private async retryOperation(record: IErrorRecord, operation: () => Promise<any>): Promise<any> {
    while (record.retryCount < this.maxRetries) {
      try {
        // 指数退避重试
        await new Promise(resolve =>
          setTimeout(resolve, this.retryDelay * Math.pow(2, record.retryCount)),
        );

        const result = await operation();
        record.resolved = true;
        await this.updateErrorRecord(record);
        return result;
      } catch (error) {
        record.retryCount++;
        record.error = error as Error;
        await this.updateErrorRecord(record);
      }
    }

    // 所有重试失败后，执行回滚
    await this.rollback(record);
    throw new Error(`操作失败，已重试 ${this.maxRetries} 次`);
  }

  private async rollback(record: IErrorRecord): Promise<void> {
    try {
      // 获取回滚点
      const snapshot = await this.db.get(`snapshot:${record.id}`);
      if (snapshot) {
        // 执行回滚
        await this.restoreSnapshot(snapshot);
      }
    } catch (error) {
      console.error('Error in error-recovery.service.ts:', '回滚失败:', error);
      throw error;
    }
  }

  private async saveErrorRecord(record: IErrorRecord): Promise<void> {
    await this.db.put(`error:${record.id}`, record);
  }

  private async updateErrorRecord(record: IErrorRecord): Promise<void> {
    await this.db.put(`error:${record.id}`, record);
  }

  private async restoreSnapshot(snapshot: any): Promise<void> {
    // 实现数据恢复逻辑
  }
}
